<mujoco>
  <asset>
    <texture name="grid" type="2d" builtin="checker" rgb1=".6 .7 .8"
     rgb2=".2 .3 .4" width="300" height="300" mark="none"/>
    <material name="grid" texture="grid" texrepeat="1 1"
     texuniform="true" reflectance=".2"/>

    <mesh name="egg_mesh" file="egg1.obj"/>

    
    <material name="siliconeMaterial"
              specular="0.2" shininess="0.1" reflectance="0.1"/>
    <material name="eggShellMaterial"
              specular="1"   shininess="1"   reflectance="0.3"/>

  </asset>

  <default> 
    <!-- <geom rgba='0.2 0.2 0.2 1'/> -->
  </default>

  <worldbody>
    <light name="light" pos="0 0 1"/>
    <body name="floor">
      <geom name="floor_geom" type="plane" pos="0 0 -.5" size="10 10 .1" material="grid"/>
    </body>

    <camera name="fixed" pos="0 -1.3 .5" xyaxes="1 0 0 0 1 2"/>


    <!-- arm body  -->
    <body name="base" pos="-0.5 -0.5 0.03">
      <geom name="base_geom" type="box" 
      size="0.4 0.4 0.1" mass="10000"
      rgba="0.1 0.1 0.1 1"/> 
      <freejoint/>

      <body name="base_1" pos="0 0 0.13">
        <geom name="base_1_geom" type="sphere" 
        size="0.2 0.2 0.2" rgba='0.2 0.2 0.2 1'/>
        <joint name="base_1_joint" type="hinge" axis="0 0 1"/>

        <!-- <joint name="base_1_joint" type="slide" axis="1 0 0" range="-0.4 0.4"/> -->


        <joint name="base_2_joint" type="hinge" axis="0 1 0"/>

        <body name="arm_base" pos="0 0 0.25">
          <geom name="arm_base_geom" type="capsule" 
          size="0.1 0.1 0.1" fromto='0 0 -0.05 -0.35 0 0.5'
          rgba="1 0.5 0 1"/>
          
          <body name="arm_base_2" pos="-0.35 0 0.6">
            <geom name="arm_base_2_geom" type="sphere" 
            size="0.1 0.1 0.1" rgba='0.2 0.2 0.2 1'/>
            <joint name="arm_base_2_joint" type="hinge" axis="0 1 0" pos="0 0 0"/>

                
            <body name="arm_base_2_1" pos="0 0 0.25">
              <geom name="arm_base_2_1_geom" type="capsule" 
              size="0.1 0.1 0.1" fromto='0.05 0 -0.15 0.5 0 0.25'
              rgba="1 0.5 0 1"/>


              <!-- handle  -->
              <body name="arm_handle" pos="0.6 0 0.3">
                <geom name="arm_hanfle_geom" size="0.1 0.1" 
                type="sphere" rgba='0.2 0.2 0.2 1'/>

                <body name="arm_handle_1" pos="0.08 0 0">
                  <geom name="arm_handle_1_geom" 
                  rgba="0.9 0.9 0 1"
                  size="0.02 0.2 0.1" type="box"/>

                  <body name="arm_finger_left" pos="0.18 0.18 0">
                    <joint name="arm_finger_left_joint" type="slide" axis="0 1 0" range="-0.15 0"/>
                    <geom name="arm_finger_left_geom" 
                    rgba="0.2 0.2 0.2 1"
                    size="0.2 0.01 0.15" 
                    material="siliconeMaterial"
                    type="box"

                    condim="6"
                    friction="6 0.005 0.0001"
                    solref="0.02 1"
                    solimp="1.2 1.1"
                    />
                  </body>

                  
                  <body name="arm_finger_right" pos="0.18 -0.18 0">
                    <joint name="arm_finger_right_joint" type="slide" axis="0 1 0" range="0 0.15"/>
                    <geom name="arm_finger_right_geom" 
                    rgba="0.2 0.2 0.2 1"
                    size="0.2 0.01 0.15" 
                    material="siliconeMaterial"
                    type="box"

                    condim="6"
                    friction="6 0.005 0.0001"
                    solref="0.02 1"
                    solimp="1.2 1.1"
                    />
                  </body>
                  
                </body>

              </body>


            </body> 


          </body> 

        </body>
      </body>
    </body> 

    <!-- egg base start -->
    <body name="egg_base_start" pos="0.5 0.5 -0.4">
      <geom type="box" pos="0 0.1 0" size="0.1 0.02 0.02" rgba="1 0 0 1"/>
      <geom type="box" pos="0 -0.1 0" size="0.1 0.02 0.02" rgba="1 0 0 1"/>
      <geom type="box" pos="0.1 0 0" size="0.02 0.1 0.02" rgba="1 0 0 1"/>
      <geom type="box" pos="-0.1 0 0" size="0.02 0.1 0.02" rgba="1 0 0 1"/>

      <freejoint/>
    </body>

    <!-- target point where to deliver the egg -->
    <body name="egg_base_target" pos="0.5 0 -0.4">
      <geom type="box" pos="0 0.15 0" size="0.1 0.02 0.02" rgba="0 1 1 1"/>
      <geom type="box" pos="0 -0.15 0" size="0.1 0.02 0.02" rgba="0 1 1 1"/>
      <geom type="box" pos="0.15 0 0" size="0.02 0.1 0.02" rgba="0 1 1 1"/>
      <geom type="box" pos="-0.15 0 0" size="0.02 0.1 0.02" rgba="0 1 1 1"/>

      <freejoint/>
    </body>
    
    <!-- egg itself -->
    <body name="egg" pos="0.5 0.5 -0.1">
      <geom name="egg_geom" type="mesh" mesh="egg_mesh" 
      euler="90 90 0" mass="100"
      rgba="1 0.6 0.3 1"
      material="eggShellMaterial"
      />
      <freejoint/>
    </body>
  </worldbody>

  <actuator>

    <!-- <motor name="m2" joint="base_1_joint" ctrlrange="-1 1" gear="100"/> -->
    <position name="p1" joint="base_1_joint"
          kp="500" kv="200"/>
          <!-- base_2_joint -->

    <position name="p2_arm" joint="base_2_joint"
          kp="1000" kv="200"/>

    <!-- <motor name="m2_arm_2" joint="arm_base_2_joint" ctrlrange="-1 1" gear="100"/> -->
    <position name="p1_arm_2" joint="arm_base_2_joint"
          kp="500" kv="200"/>
      
    
    <!-- this things simulate the servo -->
    <position name="p_leftfinger" joint="arm_finger_left_joint" kp="500" kv="200"/>
    <position name="p_rightfinger" joint="arm_finger_right_joint" kp="500" kv="200"/>
  </actuator>

</mujoco>
